INFO:root:gpu device = cuda:0
Traceback (most recent call last):
  File "main.py", line 300, in <module>
    save_model_str=get('run_dir'))
  File "main.py", line 217, in create_run_ensemble
    ensemble_model = EnsembleModel(trained_models[:1], dense_units = ensemble_config['dense_units'], out_size=train_dataset.n_classes)
  File "/home/rkohli/aml-project/src/model.py", line 289, in __init__
    self.out_classifier = nn.Linear(dense_units*len(self.models()), self.out_size)
TypeError: 'list' object is not callable
